<?xml version="1.0"?>
<robot name="RRP_Robot">

  <!-- Base Link -->
  <link name="base_link">
    <visual>
      <geometry>
        <box size="0.5 0.5 0.5"/>
      </geometry>
      <origin rpy="0 0 0" xyz="0 0 0.25"/>
      <material name="white">
        <color rgba="1.0 1.0 1.0 1.0"/>
      </material>	
    </visual>
    <collision>
      <geometry>
        <box size="0.5 0.5 0.5"/>
      </geometry>
      <origin rpy="0 0 0" xyz="0 0 0.25"/>
    </collision>
    <inertial>
      <mass value="10.0"/>
      <inertia ixx="0.3" ixy="0.0" ixz="0.0" iyy="0.3" iyz="0.0" izz="0.3"/>
    </inertial>
  </link>

  <!-- Link 1 -->
  <link name="link1">
    <visual>
      <geometry>
        <cylinder length="1.0" radius="0.1"/>
      </geometry>
      <origin rpy="0 0 0" xyz="0 0 0"/>
      <material name="red">
        <color rgba="1.0 0.0 0.0 1.0"/>
      </material>
    </visual>
    <collision>
      <geometry>
        <cylinder length="1.0" radius="0.1"/>
      </geometry>
      <origin rpy="0 0 0" xyz="0 0 0"/>
    </collision>
    <inertial>
      <mass value="0.2"/>
      <inertia ixx="0.02" ixy="0.0" ixz="0.0" iyy="0.02" iyz="0.0" izz="0.001"/>
    </inertial>
  </link>

  <!-- Joint 1: Base to Link 1 -->
  <joint name="joint1" type="revolute">
    <parent link="base_link"/>
    <child link="link1"/>
    <origin xyz="0 0 1" rpy="0 0 0"/>
    <axis xyz="0 0 1"/>
    <limit lower="-3.14159" upper="3.14159" effort="0.2" velocity="0.8"/>
  </joint>

  <!-- Link 2 -->
  <link name="link2">
    <visual>
      <geometry>
        <box size="0.5 0.2 0.1"/>
      </geometry>
      <origin rpy="0 0 0" xyz="0.25 0 0"/>
      <material name="green">
        <color rgba="0.0 1.0 0.0 1.0"/>
      </material>
    </visual>
    <collision>
      <geometry>
        <box size="1.0 0.2 0.1"/>
      </geometry>
      <origin rpy="0 0 0" xyz="0.25 0 0"/>
    </collision>
    <inertial>
      <mass value="0.2"/>
      <inertia ixx="0.001" ixy="0.0" ixz="0.0" iyy="0.05" iyz="0.0" izz="0.05"/>
    </inertial>
  </link>

  <!-- Joint 2: Link 1 to Link 2 -->
  <joint name="joint2" type="revolute">
    <parent link="link1"/>
    <child link="link2"/>
    <origin xyz="0 0.2 0.5" rpy="0 0 0"/>
    <axis xyz="0 1 0"/>
    <limit lower="-1.5708" upper="1.5708" effort="0.2" velocity="0.8"/>
  </joint>

  <!-- Prismatic Link -->
  <link name="prismatic_link">
    <visual>
      <geometry>
       <box size="0.52 0.1 0.1"/>
      </geometry>
      <origin rpy="0 0 0" xyz="0 0 0"/>
      <material name="blue">
        <color rgba="0.0 0.0 1.0 1.0"/>
      </material>
    </visual>
    <collision>
      <geometry>
       <box size="0.1 0.1 0.1"/>
      </geometry>
      <origin rpy="0 0 0" xyz="0 0 0"/>
    </collision>
    <inertial>
      <mass value="0.2"/>
      <inertia ixx="0.0003" ixy="0.0" ixz="0.0" iyy="0.0003" iyz="0.0" izz="0.0003"/>
    </inertial>
  </link>

  <!-- Joint 3: Link 2 to Prismatic Link -->
  <joint name="joint3" type="prismatic">
    <parent link="link2"/>
    <child link="prismatic_link"/>
    <origin xyz="0.26 0 0.12" rpy="0 0 0"/>
    <axis xyz="1 0 0"/>
    <limit lower="0.0" upper="0.5" effort="0.1" velocity="0.2"/>
  </joint>

  <!-- Kinect V2 Link -->
  <link name="kinect_v2_link">
    <visual>
      <geometry>
	<mesh filename="model://kinect2.STL" scale="1 1 1"/>

      </geometry>
    </visual>
    <collision>
      <geometry>
	<mesh filename="model://kinect2.STL" scale="1 1 1"/>

      </geometry>
    </collision>
    <inertial>
      <mass value="0.5"/>
      <inertia ixx="0.01" ixy="0.0" ixz="0.0" iyy="0.01" iyz="0.0" izz="0.01"/>
    </inertial>
  </link>

  <!-- Kinect V2 and End Effector Joint -->
  <joint name="kinect_v2_joint" type="fixed">
    <parent link="prismatic_link"/>
    <child link="kinect_v2_link"/>
    <origin xyz="0 0 0.15" rpy="0 0 0"/>
  </joint>
  



    <!-- Used for fixing robot to Gazebo 'base_link' 将机械手的基座固定在世界坐标上-->
    <link name="world"/>

    <joint name="fixed" type="fixed">
        <parent link="world"/>
        <child link="base_link"/>
    </joint>

<!-- 场景模型 -->
<link name="scene_model">
  <visual>
    <geometry>
      <mesh filename="model://tree-tree.dae" scale="1 1 1"/>
    </geometry>
    <origin xyz="0 0 0" rpy="0 0 0"/> 
  </visual>
  <collision>
    <geometry>
      <mesh filename="model://tree-tree.dae" scale="1 1 1"/>
    </geometry>
    <origin xyz="0 0 0" rpy="0 0 0"/>
  </collision>
  <inertial>
    <mass value="1.0"/>
    <inertia ixx="0.1" ixy="0.0" ixz="0.0" iyy="0.1" iyz="0.0" izz="0.1"/>
  </inertial>
</link>

<!-- 固定场景到世界坐标 -->
<joint name="scene_fixed_joint" type="fixed">
  <parent link="world"/>
  <child link="scene_model"/>
  <origin xyz="3 2 0" rpy="1.57 0 0"/>
</joint>








<!-- leaves -->
<!--
<link name="leaves">
  <visual>
    <geometry>
      <mesh filename="model://leaves.dae" scale="1 1 1"/>
    </geometry>
    <origin xyz="0 0 0" rpy="0 0 0"/> 
  </visual>
  <collision>
    <geometry>
      <mesh filename="model://leaves.dae" scale="1 1 1"/>
    </geometry>
    <origin xyz="0 0 0" rpy="0 0 0"/>
  </collision>
  <inertial>
    <mass value="1.0"/>
    <inertia ixx="0.1" ixy="0.0" ixz="0.0" iyy="0.1" iyz="0.0" izz="0.1"/>
  </inertial>
</link>


<joint name="leaves_fixed" type="fixed">
  <parent link="world"/>
  <child link="leaves"/>
  <origin xyz="2 0 0" rpy="1.57 0 0"/>
</joint>

<gazebo reference="leaves"> 
    <material>Gazebo/vine_leaves</material>
</gazebo>

-->


  <!-- branch -->
  <link name="branch">
    <visual>
      <geometry>
        <cylinder length="0.5" radius="0.05"/>
      </geometry>
      <origin rpy="0 0 0" xyz="0 0 0"/>
    </visual>
    <collision>
      <geometry>
        <cylinder length="0.4" radius="0.1"/>
      </geometry>
      <origin rpy="0 0 0" xyz="0 0 0"/>
    </collision>
    <inertial>
      <mass value="0.2"/>
      <inertia ixx="0.02" ixy="0.0" ixz="0.0" iyy="0.02" iyz="0.0" izz="0.001"/>
    </inertial>
  </link>

  <!-- branch_fixed -->
  <joint name="branch fixed" type="fixed">
    <parent link="world"/>
    <child link="branch"/>
    <origin xyz="2 0 1" rpy="1 0 0"/>
    <axis xyz="1 0 0"/>
  </joint>

<gazebo reference="branch"> 
    <material>Gazebo/Blacktree</material>
</gazebo>














    <gazebo reference="base_link">
        <material>Gazebo/Black</material>
        <gravity>true</gravity>
    </gazebo>
    <gazebo reference="link1">
        <material>Gazebo/Red</material>
    </gazebo>
    <gazebo reference="link2">
        <material>Gazebo/Green</material>
    </gazebo>
    <gazebo reference="prismatic_link">
        <material>Gazebo/Blue</material>
    </gazebo>
    
<gazebo reference="scene_model"> 
    <material>Gazebo/vine_leaves</material>
</gazebo>







<!-- camera kinect v2 -->
<gazebo reference="kinect_v2_link">
  <sensor type="camera" name="kinect_v2_rgb_camera">
    <update_rate>30</update_rate>
    <camera>
      <horizontal_fov>1.047</horizontal_fov>
      <image>
        <width>1920</width>
        <height>1080</height>
        <format>R8G8B8</format>
      </image>
      <clip>
        <near>0.1</near>
        <far>100</far>
      </clip>
    </camera>
    <plugin name="gazebo_ros_camera" filename="libgazebo_ros_camera.so">
      <ros>
        <namespace>/kinect_v2/rgb</namespace>
        <argument>image_raw</argument>
        <argument>camera_info</argument> <!-- RGB 相机参数话题 -->
      </ros>
    </plugin>
  </sensor>
</gazebo>

<gazebo reference="kinect_v2_link">
  <sensor type="depth" name="kinect_v2_depth_sensor">
    <update_rate>30</update_rate>
    <camera>
      <horizontal_fov>1.047</horizontal_fov>
      <image>
        <width>512</width>
        <height>424</height>
        <format>FLOAT32</format>
      </image>
      <clip>
        <near>0.1</near>
        <far>10.0</far>
      </clip>
    </camera>
    <plugin name="gazebo_ros_depth_camera" filename="libgazebo_ros_camera.so">
      <ros>
        <namespace>/kinect_v2/depth</namespace>
        <argument>depth/image_raw</argument>
        <argument>depth/camera_info</argument> <!-- 深度相机参数话题 -->
      </ros>
    </plugin>
  </sensor>
</gazebo>







<!--ROS2_CONTROL gazebo交互接口-->

<ros2_control name="GazeboSystem" type="system">
    <hardware>
        <plugin>gazebo_ros2_control/GazeboSystem</plugin>
    </hardware>
    <joint name="joint1">
        <command_interface name="position">
            <param name="min">-3.14</param>
            <param name="max">3.14</param>
        </command_interface>
        <state_interface name="position">
            <param name="initial_value">0.0</param>
        </state_interface>
        <state_interface name="velocity"/>
    </joint>
    <joint name="joint2">
        <command_interface name="position">
            <param name="min">-1.57</param>
            <param name="max">1.57</param>
        </command_interface>
        <state_interface name="position">
            <param name="initial_value">0.0</param>
        </state_interface>
        <state_interface name="velocity"/>
    </joint>
    <joint name="joint3">
        <command_interface name="position">
            <param name="min">0</param>
            <param name="max">0.5</param>
        </command_interface>
        <state_interface name="position">
            <param name="initial_value">0.0</param>
        </state_interface>
        <state_interface name="velocity"/>
    </joint>
</ros2_control>



    <gazebo>
        <plugin filename="libgazebo_ros2_control.so" name="gazebo_ros2_control">
            <parameters>$(find mybot)/config/ros2_controllers.yaml</parameters>
            <robot_param_node>robot_state_publisher</robot_param_node>
        </plugin>
    </gazebo>




</robot>
